<?xml version='1.0'?>
<robot name="SimpHex">
  <link name="body">

    <inertial>
      <mass value="4.4" />
      <inertia ixx=".0766"  ixy="0"  ixz="0" iyy=".0253" iyz="0" izz=".0972" />
    </inertial>

    <collision name="collision1">
      <origin xyz="0 0 0" rpy="0 0 0" />
      <geometry>
        <box size="0.25 0.45 0.08" />
      </geometry>
    </collision>
    
    <visual name="visual1">
      <origin xyz="0 0 0" rpy="0 0 0" />
      <geometry>
        <box size="0.25 0.45 0.08" />
      </geometry>
    </visual>

    <collision name="collision2">
      <origin xyz=".1375 0 0" rpy="0 0 0" />
      <geometry>
        <box size="0.025 0.05 0.03" />
      </geometry>
    </collision>

    <visual name="visual2">
      <origin xyz=".1375 0 0" rpy="0 0 0" />
      <geometry>
        <box size="0.025 0.05 0.03" />
      </geometry>
    </visual>

    <collision name="collision3">
      <origin xyz="-.1375 0 0" rpy="0 0 0" />
      <geometry>
        <box size="0.025 0.05 0.03" />
      </geometry>
    </collision>

    <visual name="visual3">
      <origin xyz="-.1375 0 0" rpy="0 0 0" />
      <geometry>
        <box size="0.025 0.05 0.03" />
      </geometry>
    </visual>
  
  </link>
  <link name="leg_1">

    <inertial>
      <mass value="0.05" />
      <inertia ixx="0"  ixy="0"  ixz="0" iyy="0" iyz="0" izz="0" />
    </inertial>

    <collision name="collision">
      <origin xyz=".15 .19 0" rpy="0 3.14 0" />
      <geometry>
        <mesh filename="package://simphex_description/meshes/simpLeg12.STL" scale="0.01 0.01 0.01"/>
      </geometry>
    </collision>
    
    <visual name="visual">
      <origin xyz=".15 .19 0" rpy="0 3.14 0" />
      <geometry>
        <mesh filename="package://simphex_description/meshes/simpLeg12.STL" scale="0.01 0.01 0.01"/>
      </geometry>
    </visual>

  </link>

  <link name="leg_2">

    <inertial>
      <mass value="0.05" />
      <inertia ixx="0"  ixy="0"  ixz="0" iyy="0" iyz="0" izz="0" />
    </inertial>

    <collision name="collision">
      <origin xyz=".175 0 0" rpy="0 3.14 0" />
      <geometry>
        <mesh filename="package://simphex_description/meshes/simpLeg12.STL" scale="0.01 0.01 0.01"/>
      </geometry>
    </collision>
    
    <visual name="visual">
      <origin xyz=".175 0 0" rpy="0 3.14 0" />
      <geometry>
        <mesh filename="package://simphex_description/meshes/simpLeg12.STL" scale="0.01 0.01 0.01"/>
      </geometry>
    </visual>

  </link>

  <link name="leg_3">

    <inertial>
      <mass value="0.05" />
      <inertia ixx="0"  ixy="0"  ixz="0" iyy="0" iyz="0" izz="0" />
    </inertial>

    <collision name="collision">
      <origin xyz=".15 -.19 0" rpy="0 3.14 0" />
      <geometry>
        <mesh filename="package://simphex_description/meshes/simpLeg12.STL" scale="0.01 0.01 0.01"/>
      </geometry>
    </collision>
    
    <visual name="visual">
      <origin xyz=".15 -.19 0" rpy="0 3.14 0" />
      <geometry>
        <mesh filename="package://simphex_description/meshes/simpLeg12.STL" scale="0.01 0.01 0.01"/>
      </geometry>
    </visual>

  </link>

  <link name="leg_4">

    <inertial>
      <mass value="0.05" />
      <inertia ixx="0"  ixy="0"  ixz="0" iyy="0" iyz="0" izz="0" />
    </inertial>

    <collision name="collision">
      <origin xyz="-.125 .19 0" rpy="0 3.14 0" />
      <geometry>
        <mesh filename="package://simphex_description/meshes/simpLeg12.STL" scale="0.01 0.01 0.01"/>
      </geometry>
    </collision>
    
    <visual name="visual">
      <origin xyz="-.125 .19 0" rpy="0 3.14 0" />
      <geometry>
        <mesh filename="package://simphex_description/meshes/simpLeg12.STL" scale="0.01 0.01 0.01"/>
      </geometry>
    </visual>

  </link>

  <link name="leg_5">

    <inertial>
      <mass value="0.05" />
      <inertia ixx="0"  ixy="0"  ixz="0" iyy="0" iyz="0" izz="0" />
    </inertial>

    <collision name="collision">
      <origin xyz="-.15 0 0" rpy="0 3.14 0" />
      <geometry>
        <mesh filename="package://simphex_description/meshes/simpLeg12.STL" scale="0.01 0.01 0.01"/>
      </geometry>
    </collision>
    
    <visual name="visual">
      <origin xyz="-.15 0 0" rpy="0 3.14 0" />
      <geometry>
        <mesh filename="package://simphex_description/meshes/simpLeg12.STL" scale="0.01 0.01 0.01"/>
      </geometry>
    </visual>

  </link>

  <link name="leg_6">

    <inertial>
      <mass value="0.05" />
      <inertia ixx="0"  ixy="0"  ixz="0" iyy="0" iyz="0" izz="0" />
    </inertial>

    <collision name="collision">
      <origin xyz="-.125 -.19 0" rpy="0 3.14 0" />
      <geometry>
        <mesh filename="package://simphex_description/meshes/simpLeg12.STL" scale="0.01 0.01 0.01"/>
      </geometry>
    </collision>
    
    <visual name="visual">
      <origin xyz="-.125 -.19 0" rpy="0 3.14 0" />
      <geometry>
        <mesh filename="package://simphex_description/meshes/simpLeg12.STL" scale="0.01 0.01 0.01"/>
      </geometry>
    </visual>

  </link>

  <joint type="continuous" name="leg_1_joint">
    <origin xyz="0 0 0" rpy="0 0 0" />
    <child link="leg_1" />
    <parent link="body" />
    <axis xyz="1 0 0" />
  </joint>

  <joint type="continuous" name="leg_2_joint">
    <origin xyz="0 0 0" rpy="0 0 0" />
    <child link="leg_2" />
    <parent link="body" />
    <axis xyz="1 0 0" />
  </joint>

  <joint type="continuous" name="leg_3_joint">
    <origin xyz="0 0 0" rpy="0 0 0" />
    <child link="leg_3" />
    <parent link="body" />
    <axis xyz="1 0 0" />
  </joint>

  <joint type="continuous" name="leg_4_joint">
    <origin xyz="0 0 0" rpy="0 0 0" />
    <child link="leg_4" />
    <parent link="body" />
    <axis xyz="1 0 0" />
  </joint>

  <joint type="continuous" name="leg_5_joint">
    <origin xyz="0 0 0" rpy="0 0 0" />
    <child link="leg_5" />
    <parent link="body" />
    <axis xyz="1 0 0" />
  </joint>

  <joint type="continuous" name="leg_6_joint">
    <origin xyz="0 0 0" rpy="0 0 0" />
    <child link="leg_6" />
    <parent link="body" />
    <axis xyz="1 0 0" />
  </joint>

  <transmission name="simple_trans">
    <type>transmission_interface/SimpleTransmission</type>
    <joint name="leg_1_joint">
      <hardwareInterface>EffortJointInterface</hardwareInterface>
    </joint>
    <actuator name="leg_1_motor">
      <mechanicalReduction>50</mechanicalReduction>
    </actuator>
  </transmission>
</robot>